Workbook

Sheet Config
A1: Parâmetro | B1: Valor
A2: theta_shade | B2: 0
A3: rho_empate | B3: 1.1
A4: delta_desempate | B4: 0.05
A5: w_por_flag | B5: 0.05
A6: cap_excecao_pct_lambda | B6: 0.1
A7: tripwire_gols | B7: 0.4

Sheet Tabelas
A1: lambda_total | B1: p_over_2.5
A2: 0.2 | B2: 0.0011484812
A3: 0.21 | B3: 0.0013196798
A4: 0.22 | B4: 0.0015061116
A5: 0.23 | B5: 0.0017082551
A6: 0.24 | B6: 0.0019265699
A7: 0.25 | B7: 0.0021614967
A8: 0.26 | B8: 0.0024134583
A9: 0.27 | B9: 0.0026828596
A10: 0.28 | B10: 0.0029700883
A11: 0.29 | B11: 0.0032755148
A12: 0.3 | B12: 0.0035994932
A13: 0.31 | B13: 0.0039423611
... A582: 6 | B582: 0.9380312
B600: -3 | C600: -2.95 | D600: -2.9 | E600: -2.85 | F600: -2.8 | G600: -2.75 | H600: -2.7 | I600: -2.65 | J600: -2.6 | K600: -2.55 | L600: -2.5 | M600: -2.45 | N600: -2.4 | O600: -2.35 | P600: -2.3 | Q600: -2.25 | R600: -2.2 | S600: -2.15 | T600: -2.1 | U600: -2.05 | V600: -2 | W600: -1.95 | X600: -1.9 | Y600: -1.85 | Z600: -1.8 | AA600: -1.75 | AB600: -1.7 | AC600: -1.65 | AD600: -1.6 | AE600: -1.55 | AF600: -1.5 | AG600: -1.45 | AH600: -1.4 | AI600: -1.35 | AJ600: -1.3 | AK600: -1.25 | AL600: -1.2 | AM600: -1.15 | AN600: -1.1 | AO600: -1.05 | AP600: -1 | AQ600: -0.95 | AR600: -0.9 | AS600: -0.85 | AT600: -0.8 | AU600: -0.75 | AV600: -0.7 | AW600: -0.65 | AX600: -0.6 | AY600: -0.55 | AZ600: -0.5 | BA600: -0.45 | BB600: -0.4 | BC600: -0.35 | BD600: -0.3 | BE600: -0.25 | BF600: -0.2 | BG600: -0.15 | BH600: -0.1 | BI600: -0.05 | BJ600: 0 | BK600: 0.05 | BL600: 0.1 | BM600: 0.15 | BN600: 0.2 | BO600: 0.25 | BP600: 0.3 | BQ600: 0.35 | BR600: 0.4 | BS600: 0.45 | BT600: 0.5 | BU600: 0.55 | BV600: 0.6 | BW600: 0.65 | BX600: 0.7 | BY600: 0.75 | BZ600: 0.8 | CA600: 0.85 | CB600: 0.9 | CC600: 0.95 | CD600: 1 | CE600: 1.05 | CF600: 1.1 | CG600: 1.15 | CH600: 1.2 | CI600: 1.25 | CJ600: 1.3 | CK600: 1.35 | CL600: 1.4 | CM600: 1.45 | CN600: 1.5 | CO600: 1.55 | CP600: 1.6 | CQ600: 1.65 | CR600: 1.7 | CS600: 1.75 | CT600: 1.8 | CU600: 1.85 | CV600: 1.9 | CW600: 1.95 | CX600: 2 | CY600: 2.05 | CZ600: 2.1 | DA600: 2.15 | DB600: 2.2 | DC600: 2.25 | DD600: 2.3 | DE600: 2.35 | DF600: 2.4 | DG600: 2.45 | DH600: 2.5 | DI600: 2.55 | DJ600: 2.6 | DK600: 2.65 | DL600: 2.7 | DM600: 2.75 | DN600: 2.8 | DO600: 2.85 | DP600: 2.9 | DQ600: 2.95 | DR600: 3
A601: 0.6 | B601: 0 | C601: 0 | D601: 0 | E601: 0 | F601: 0 | G601: 0 | H601: 0 | I601: 0 | J601: 0 | K601: 0 | L601: 0 | M601: 0 | N601: 0 | O601: 0 | P601: 0 | Q601: 0 | R601: 0 | S601: 0 | T601: 0 | U601: 0 | V601: 0 | W601: 0 | X601: 0 | Y601: 0 | Z601: 0 | AA601: 0 | AB601: 0 | AC601: 0 | AD601: 0 | AE601: 0 | AF601: 0 | AG601: 0 | AH601: 0 | AI601: 0 | AJ601: 0 | AK601: 0 | AL601: 0 | AM601: 0 | AN601: 0 | AO601: 0 | AP601: 0 | AQ601: 0 | AR601: 0 | AS601: 0 | AT601: 0 | AU601: 0 | AV601: 0 | AW601: 0 | AX601: 0 | AY601: 0.013992912 | AZ601: 0.028523605 | BA601: 0.043580164 | BB601: 0.059149728 | BC601: 0.075218507 | BD601: 0.091771809 | BE601: 0.10879406 | BF601: 0.12626884 | BG601: 0.14417889 | BH601: 0.16250616 | BI601: 0.18123185 | BJ601: 0.2003364 | BK601: 0.21979957 | BL601: 0.23960045 | BM601: 0.25971752 | BN601: 0.28012865 | BO601: 0.30081118 | BP601: 0.32174193 | BQ601: 0.34289727 | BR601: 0.36425314 | BS601: 0.38578509 | BT601: 0.40746836 | BU601: 0.42927789 | BV601: 1 | BW601: 1 | BX601: 1 | BY601: 1 | BZ601: 1 | CA601: 1 | CB601: 1 | CC601: 1 | CD601: 1 | CE601: 1 | CF601: 1 | CG601: 1 | CH601: 1 | CI601: 1 | CJ601: 1 | CK601: 1 | CL601: 1 | CM601: 1 | CN601: 1 | CO601: 1 | CP601: 1 | CQ601: 1 | CR601: 1 | CS601: 1 | CT601: 1 | CU601: 1 | CV601: 1 | CW601: 1 | CX601: 1 | CY601: 1 | CZ601: 1 | DA601: 1 | DB601: 1 | DC601: 1 | DD601: 1 | DE601: 1 | DF601: 1 | DG601: 1 | DH601: 1 | DI601: 1 | DJ601: 1 | DK601: 1 | DL601: 1 | DM601: 1 | DN601: 1 | DO601: 1 | DP601: 1 | DQ601: 1 | DR601: 1
A602: 0.65 | B602: 0 | C602: 0 | D602: 0 | E602: 0 | F602: 0 | G602: 0 | H602: 0 | I602: 0 | J602: 0 | K602: 0 | L602: 0 | M602: 0 | N602: 0 | O602: 0 | P602: 0 | Q602: 0 | R602: 0 | S602: 0 | T602: 0 | U602: 0 | V602: 0 | W602: 0 | X602: 0 | Y602: 0 | Z602: 0 | AA602: 0 | AB602: 0 | AC602: 0 | AD602: 0 | AE602: 0 | AF602: 0 | AG602: 0 | AH602: 0 | AI602: 0 | AJ602: 0 | AK602: 0 | AL602: 0 | AM602: 0 | AN602: 0 | AO602: 0 | AP602: 0 | AQ602: 0 | AR602: 0 | AS602: 0 | AT602: 0 | AU602: 0 | AV602: 0 | AW602: 0 | AX602: 0.013318736 | AY602: 0.027165989 | AZ602: 0.041531052 | BA602: 0.056402292 | BB602: 0.071767169 | BC602: 0.087612254 | BD602: 0.10392325 | BE602: 0.12068502 | BF602: 0.13788161 | BG602: 0.15549627 | BH602: 0.17351149 | BI602: 0.19190902 | BJ602: 0.21066993 | BK602: 0.22977461 | BL602: 0.2492028 | BM602: 0.26893367 | BN602: 0.28894581 | BO602: 0.30921731 | BP602: 0.32972574 | BQ602: 0.35044826 | BR602: 0.37136162 | BS602: 0.3924422 | BT602: 0.41366606 | BU602: 0.43500901 | BV602: 0.4564466 | BW602: 1 | BX602: 1 | BY602: 1 | BZ602: 1 | CA602: 1 | CB602: 1 | CC602: 1 | CD602: 1 | CE602: 1 | CF602: 1 | CG602: 1 | CH602: 1 | CI602: 1 | CJ602: 1 | CK602: 1 | CL602: 1 | CM602: 1 | CN602: 1 | CO602: 1 | CP602: 1 | CQ602: 1 | CR602: 1 | CS602: 1 | CT602: 1 | CU602: 1 | CV602: 1 | CW602: 1 | CX602: 1 | CY602: 1 | CZ602: 1 | DA602: 1 | DB602: 1 | DC602: 1 | DD602: 1 | DE602: 1 | DF602: 1 | DG602: 1 | DH602: 1 | DI602: 1 | DJ602: 1 | DK602: 1 | DL602: 1 | DM602: 1 | DN602: 1 | DO602: 1 | DP602: 1 | DQ602: 1 | DR602: 1
A603: 0.7 | B603: 0 | C603: 0 | D603: 0 | E603: 0 | F603: 0 | G603: 0 | H603: 0 | I603: 0 | J603: 0 | K603: 0 | L603: 0 | M603: 0 | N603: 0 | O603: 0 | P603: 0 | Q603: 0 | R603: 0 | S603: 0 | T603: 0 | U603: 0 | V603: 0 | W603: 0 | X603: 0 | Y603: 0 | Z603: 0 | AA603: 0 | AB603: 0 | AC603: 0 | AD603: 0 | AE603: 0 | AF603: 0 | AG603: 0 | AH603: 0 | AI603: 0 | AJ603: 0 | AK603: 0 | AL603: 0 | AM603: 0 | AN603: 0 | AO603: 0 | AP603: 0 | AQ603: 0 | AR603: 0 | AS603: 0 | AT603: 0 | AU603: 0 | AV603: 0 | AW603: 0.012677041 | AX603: 0.025872977 | AY603: 0.039578243 | AZ603: 0.053782367 | BA603: 0.06847399 | BB603: 0.08364088 | BC603: 0.099269954 | BD603: 0.1153473 | BE603: 0.13185819 | BF603: 0.14878713 | BG603: 0.16611784 | BH603: 0.18383334 | BI603: 0.20191593 | BJ603: 0.22034724 | BK603: 0.23910826 | BL603: 0.2581794 | BM603: 0.27754045 | BN603: 0.29717072 | BO603: 0.31704897 | BP603: 0.33715352 | BQ603: 0.35746229 | BR603: 0.37795277 | BS603: 0.39860215 | BT603: 0.41938729 | BU603: 0.44028481 | BV603: 0.46127109 | BW603: 0.48232236 | BX603: 1 | BY603: 1 | BZ603: 1 | CA603: 1 | CB603: 1 | CC603: 1 | CD603: 1 | CE603: 1 | CF603: 1 | CG603: 1 | CH603: 1 | CI603: 1 | CJ603: 1 | CK603: 1 | CL603: 1 | CM603: 1 | CN603: 1 | CO603: 1 | CP603: 1 | CQ603: 1 | CR603: 1 | CS603: 1 | CT603: 1 | CU603: 1 | CV603: 1 | CW603: 1 | CX603: 1 | CY603: 1 | CZ603: 1 | DA603: 1 | DB603: 1 | DC603: 1 | DD603: 1 | DE603: 1 | DF603: 1 | DG603: 1 | DH603: 1 | DI603: 1 | DJ603: 1 | DK603: 1 | DL603: 1 | DM603: 1 | DN603: 1 | DO603: 1 | DP603: 1 | DQ603: 1 | DR603: 1
A604: 0.75 | B604: 0 | C604: 0 | D604: 0 | E604: 0 | F604: 0 | G604: 0 | H604: 0 | I604: 0 | J604: 0 | K604: 0 | L604: 0 | M604: 0 | N604: 0 | O604: 0 | P604: 0 | Q604: 0 | R604: 0 | S604: 0 | T604: 0 | U604: 0 | V604: 0 | W604: 0 | X604: 0 | Y604: 0 | Z604: 0 | AA604: 0 | AB604: 0 | AC604: 0 | AD604: 0 | AE604: 0 | AF604: 0 | AG604: 0 | AH604: 0 | AI604: 0 | AJ604: 0 | AK604: 0 | AL604: 0 | AM604: 0 | AN604: 0 | AO604: 0 | AP604: 0 | AQ604: 0 | AR604: 0 | AS604: 0 | AT604: 0 | AU604: 0 | AV604: 0.01206626 | AW604: 0.024641496 | AX604: 0.037717215 | AY604: 0.051284041 | AZ604: 0.065331732 | BA604: 0.079849191 | BB604: 0.094824485 | BC604: 0.11024486 | BD604: 0.12609678 | BE604: 0.14236591 | BF604: 0.15903719 | BG604: 0.17609481 | BH604: 0.19352227 | BI604: 0.2113024 | BJ604: 0.22941739 | BK604: 0.24784881 | BL604: 0.26657766 | BM604: 0.28558438 | BN604: 0.30484891 | BO604: 0.3243507 | BP604: 0.34406879 | BQ604: 0.36398177 | BR604: 0.3840679 | BS604: 0.4043051 | BT604: 0.42467102 | BU604: 0.44514302 | BV604: 0.46569831 | BW604: 0.4863139 | BX604: 0.50696667 | BY604: 1 | BZ604: 1 | CA604: 1 | CB604: 1 | CC604: 1 | CD604: 1 | CE604: 1 | CF604: 1 | CG604: 1 | CH604: 1 | CI604: 1 | CJ604: 1 | CK604: 1 | CL604: 1 | CM604: 1 | CN604: 1 | CO604: 1 | CP604: 1 | CQ604: 1 | CR604: 1 | CS604: 1 | CT604: 1 | CU604: 1 | CV604: 1 | CW604: 1 | CX604: 1 | CY604: 1 | CZ604: 1 | DA604: 1 | DB604: 1 | DC604: 1 | DD604: 1 | DE604: 1 | DF604: 1 | DG604: 1 | DH604: 1 | DI604: 1 | DJ604: 1 | DK604: 1 | DL604: 1 | DM604: 1 | DN604: 1 | DO604: 1 | DP604: 1 | DQ604: 1 | DR604: 1
A605: 0.8 | B605: 0 | C605: 0 | D605: 0 | E605: 0 | F605: 0 | G605: 0 | H605: 0 | I605: 0 | J605: 0 | K605: 0 | L605: 0 | M605: 0 | N605: 0 | O605: 0 | P605: 0 | Q605: 0 | R605: 0 | S605: 0 | T605: 0 | U605: 0 | V605: 0 | W605: 0 | X605: 0 | Y605: 0 | Z605: 0 | AA605: 0 | AB605: 0 | AC605: 0 | AD605: 0 | AE605: 0 | AF605: 0 | AG605: 0 | AH605: 0 | AI605: 0 | AJ605: 0 | AK605: 0 | AL605: 0 | AM605: 0 | AN605: 0 | AO605: 0 | AP605: 0 | AQ605: 0 | AR605: 0 | AS605: 0 | AT605: 0 | AU605: 0.011484905 | AV605: 0.023468618 | AW605: 0.035943655 | AX605: 0.048901675 | AY605: 0.062333489 | AZ605: 0.076229073 | BA605: 0.090577586 | BB605: 0.10536738 | BC605: 0.12058604 | BD605: 0.13622035 | BE605: 0.15225638 | BF605: 0.16867948 | BG605: 0.18547429 | BH605: 0.20262479 | BI605: 0.22011429 | BJ605: 0.23792553 | BK605: 0.25604062 | BL605: 0.27444115 | BM605: 0.29310816 | BN605: 0.31202221 | BO605: 0.33116341 | BP605: 0.35051145 | BQ605: 0.37004561 | BR605: 0.38974486 | BS605: 0.40958783 | BT605: 0.42955289 | BU605: 0.44961817 | BV605: 0.46976161 | BW605: 0.48996098 | BX605: 0.51019395 | BY605: 0.53043812 | BZ605: 1 | CA605: 1 | CB605: 1 | CC605: 1 | CD605: 1 | CE605: 1 | CF605: 1 | CG605: 1 | CH605: 1 | CI605: 1 | CJ605: 1 | CK605: 1 | CL605: 1 | CM605: 1 | CN605: 1 | CO605: 1 | CP605: 1 | CQ605: 1 | CR605: 1 | CS605: 1 | CT605: 1 | CU605: 1 | CV605: 1 | CW605: 1 | CX605: 1 | CY605: 1 | CZ605: 1 | DA605: 1 | DB605: 1 | DC605: 1 | DD605: 1 | DE605: 1 | DF605: 1 | DG605: 1 | DH605: 1 | DI605: 1 | DJ605: 1 | DK605: 1 | DL605: 1 | DM605: 1 | DN605: 1 | DO605: 1 | DP605: 1 | DQ605: 1 | DR605: 1
A606: 0.85 | B606: 0 | C606: 0 | D606: 0 | E606: 0 | F606: 0 | G606: 0 | H606: 0 | I606: 0 | J606: 0 | K606: 0 | L606: 0 | M606: 0 | N606: 0 | O606: 0 | P606: 0 | Q606: 0 | R606: 0 | S606: 0 | T606: 0 | U606: 0 | V606: 0 | W606: 0 | X606: 0 | Y606: 0 | Z606: 0 | AA606: 0 | AB606: 0 | AC606: 0 | AD606: 0 | AE606: 0 | AF606: 0 | AG606: 0 | AH606: 0 | AI606: 0 | AJ606: 0 | AK606: 0 | AL606: 0 | AM606: 0 | AN606: 0 | AO606: 0 | AP606: 0 | AQ606: 0 | AR606: 0 | AS606: 0 | AT606: 0.010931559 | AU606: 0.022351556 | AV606: 0.034253456 | AW606: 0.046629891 | AX606: 0.059472668 | AY606: 0.072772778 | AZ606: 0.086520413 | BA606: 0.10070498 | BB606: 0.1153151 | BC606: 0.13033867 | BD606: 0.14576282 | BE606: 0.16157399 | BF606: 0.17775792 | BG606: 0.19429968 | BH606: 0.2111837 | BI606: 0.22839379 | BJ606: 0.24591317 | BK606: 0.26372451 | BL606: 0.28180992 | BM606: 0.30015105 | BN606: 0.31872905 | BO606: 0.33752463 | BP606: 0.35651814 | BQ606: 0.3756895 | BR606: 0.39501836 | BS606: 0.41448402 | BT606: 0.43406557 | BU606: 0.45374182 | BV606: 0.47349146 | BW606: 0.49329297 | BX606: 0.51312477 | BY606: 0.53296519 | BZ606: 0.55279252 | CA606: 1 | CB606: 1 | CC606: 1 | CD606: 1 | CE606: 1 | CF606: 1 | CG606: 1 | CH606: 1 | CI606: 1 | CJ606: 1 | CK606: 1 | CL606: 1 | CM606: 1 | CN606: 1 | CO606: 1 | CP606: 1 | CQ606: 1 | CR606: 1 | CS606: 1 | CT606: 1 | CU606: 1 | CV606: 1 | CW606: 1 | CX606: 1 | CY606: 1 | CZ606: 1 | DA606: 1 | DB606: 1 | DC606: 1 | DD606: 1 | DE606: 1 | DF606: 1 | DG606: 1 | DH606: 1 | DI606: 1 | DJ606: 1 | DK606: 1 | DL606: 1 | DM606: 1 | DN606: 1 | DO606: 1 | DP606: 1 | DQ606: 1 | DR606: 1
A607: 0.9 | B607: 0 | C607: 0 | D607: 0 | E607: 0 | F607: 0 | G607: 0 | H607: 0 | I607: 0 | J607: 0 | K607: 0 | L607: 0 | M607: 0 | N607: 0 | O607: 0 | P607: 0 | Q607: 0 | R607: 0 | S607: 0 | T607: 0 | U607: 0 | V607: 0 | W607: 0 | X607: 0 | Y607: 0 | Z607: 0 | AA607: 0 | AB607: 0 | AC607: 0 | AD607: 0 | AE607: 0 | AF607: 0 | AG607: 0 | AH607: 0 | AI607: 0 | AJ607: 0 | AK607: 0 | AL607: 0 | AM607: 0 | AN607: 0 | AO607: 0 | AP607: 0 | AQ607: 0 | AR607: 0 | AS607: 0.010404872 | AT607: 0.021287653 | AU607: 0.032642699 | AV607: 0.04446356 | AW607: 0.056742979 | AX607: 0.069472908 | AY607: 0.082644514 | AZ607: 0.096248196 | BA607: 0.11027359 | BB607: 0.12470961 | BC607: 0.13954442 | BD607: 0.1547655 | BE607: 0.17035964 | BF607: 0.18631295 | BG607: 0.20261092 | BH607: 0.21923842 | BI607: 0.23617972 | BJ607: 0.25341852 | BK607: 0.27093799 | BL607: 0.2887208 | BM607: 0.30674913 | BN607: 0.32500471 | BO607: 0.34346884 | BP607: 0.36212247 | BQ607: 0.38094618 | BR607: 0.39992021 | BS607: 0.41902455 | BT607: 0.43823894 | BU607: 0.45754289 | BV607: 0.47691574 | BW607: 0.4963367 | BX607: 0.51578488 | BY607: 0.53523932 | BZ607: 0.55467902 | CA607: 0.574083 | CB607: 1 | CC607: 1 | CD607: 1 | CE607: 1 | CF607: 1 | CG607: 1 | CH607: 1 | CI607: 1 | CJ607: 1 | CK607: 1 | CL607: 1 | CM607: 1 | CN607: 1 | CO607: 1 | CP607: 1 | CQ607: 1 | CR607: 1 | CS607: 1 | CT607: 1 | CU607: 1 | CV607: 1 | CW607: 1 | CX607: 1 | CY607: 1 | CZ607: 1 | DA607: 1 | DB607: 1 | DC607: 1 | DD607: 1 | DE607: 1 | DF607: 1 | DG607: 1 | DH607: 1 | DI607: 1 | DJ607: 1 | DK607: 1 | DL607: 1 | DM607: 1 | DN607: 1 | DO607: 1 | DP607: 1 | DQ607: 1 | DR607: 1
A608: 0.95 | B608: 0 | C608: 0 | D608: 0 | E608: 0 | F608: 0 | G608: 0 | H608: 0 | I608: 0 | J608: 0 | K608: 0 | L608: 0 | M608: 0 | N608: 0 | O608: 0 | P608: 0 | Q608: 0 | R608: 0 | S608: 0 | T608: 0 | U608: 0 | V608: 0 | W608: 0 | X608: 0 | Y608: 0 | Z608: 0 | AA608: 0 | AB608: 0 | AC608: 0 | AD608: 0 | AE608: 0 | AF608: 0 | AG608: 0 | AH608: 0 | AI608: 0 | AJ608: 0 | AK608: 0 | AL608: 0 | AM608: 0 | AN608: 0 | AO608: 0 | AP608: 0 | AQ608: 0 | AR608: 0.0099035598 | AS608: 0.02027438 | AT608: 0.031107654 | AU608: 0.042397792 | AV608: 0.054138421 | AW608: 0.066322396 | AX608: 0.078941811 | AY608: 0.091988004 | AZ608: 0.10545157 | BA608: 0.11932239 | BB608: 0.13358962 | BC608: 0.14824172 | BD608: 0.16326647 | BE608: 0.17865102 | BF608: 0.19438185 | BG608: 0.21044483 | BH608: 0.22682525 | BI608: 0.24350783 | BJ608: 0.26047673 | BK608: 0.27771562 | BL608: 0.29520767 | BM608: 0.31293558 | BN608: 0.33088163 | BO608: 0.34902771 | BP608: 0.36735533 | BQ608: 0.38584567 | BR608: 0.40447959 | BS608: 0.42323771 | BT608: 0.44210039 | BU608: 0.4610478 | BV608: 0.48005994 | BW608: 0.49911669 | BX608: 0.5181978 | BY608: 0.53728301 | BZ608: 0.55635201 | CA608: 0.57538448 | CB608: 0.59436019 | CC608: 1 | CD608: 1 | CE608: 1 | CF608: 1 | CG608: 1 | CH608: 1 | CI608: 1 | CJ608: 1 | CK608: 1 | CL608: 1 | CM608: 1 | CN608: 1 | CO608: 1 | CP608: 1 | CQ608: 1 | CR608: 1 | CS608: 1 | CT608: 1 | CU608: 1 | CV608: 1 | CW608: 1 | CX608: 1 | CY608: 1 | CZ608: 1 | DA608: 1 | DB608: 1 | DC608: 1 | DD608: 1 | DE608: 1 | DF608: 1 | DG608: 1 | DH608: 1 | DI608: 1 | DJ608: 1 | DK608: 1 | DL608: 1 | DM608: 1 | DN608: 1 | DO608: 1 | DP608: 1 | DQ608: 1 | DR608: 1
A609: 1 | B609: 0 | C609: 0 | D609: 0 | E609: 0 | F609: 0 | G609: 0 | H609: 0 | I609: 0 | J609: 0 | K609: 0 | L609: 0 | M609: 0 | N609: 0 | O609: 0 | P609: 0 | Q609: 0 | R609: 0 | S609: 0 | T609: 0 | U609: 0 | V609: 0 | W609: 0 | X609: 0 | Y609: 0 | Z609: 0 | AA609: 0 | AB609: 0 | AC609: 0 | AD609: 0 | AE609: 0 | AF609: 0 | AG609: 0 | AH609: 0 | AI609: 0 | AJ609: 0 | AK609: 0 | AL609: 0 | AM609: 0 | AN609: 0 | AO609: 0 | AP609: 0 | AQ609: 0.0094263997 | AR609: 0.019309328 | AS609: 0.029644763 | AT609: 0.040427922 | AU609: 0.051653264 | AV609: 0.063314497 | AW609: 0.075404586 | AX609: 0.087915762 | AY609: 0.10083953 | AZ609: 0.11416668 | BA609: 0.12788731 | BB609: 0.14199084 | BC609: 0.15646599 | BD609: 0.17130086 | BE609: 0.18648291 | BF609: 0.20199898 | BG609: 0.21783533 | BH609: 0.23397764 | BI609: 0.25041106 | BJ609: 0.2671202 | BK609: 0.28408919 | BL609: 0.30130168 | BM609: 0.3187409 | BN609: 0.33638965 | BO609: 0.35423035 | BP609: 0.37224507 | BQ609: 0.39041556 | BR609: 0.40872328 | BS609: 0.42714944 | BT609: 0.44567501 | BU609: 0.46428078 | BV609: 0.48294738 | BW609: 0.50165531 | BX609: 0.520385 | BY609: 0.53911679 | BZ609: 0.55783104 | CA609: 0.57650809 | CB609: 0.59512835 | CC609: 0.61367231 | CD609: 1 | CE609: 1 | CF609: 1 | CG609: 1 | CH609: 1 | CI609: 1 | CJ609: 1 | CK609: 1 | CL609: 1 | CM609: 1 | CN609: 1 | CO609: 1 | CP609: 1 | CQ609: 1 | CR609: 1 | CS609: 1 | CT609: 1 | CU609: 1 | CV609: 1 | CW609: 1 | CX609: 1 | CY609: 1 | CZ609: 1 | DA609: 1 | DB609: 1 | DC609: 1 | DD609: 1 | DE609: 1 | DF609: 1 | DG609: 1 | DH609: 1 | DI609: 1 | DJ609: 1 | DK609: 1 | DL609: 1 | DM609: 1 | DN609: 1 | DO609: 1 | DP609: 1 | DQ609: 1 | DR609: 1
A610: 1.05 | B610: 0 | C610: 0 | D610: 0 | E610: 0 | F610: 0 | G610: 0 | H610: 0 | I610: 0 | J610: 0 | K610: 0 | L610: 0 | M610: 0 | N610: 0 | O610: 0 | P610: 0 | Q610: 0 | R610: 0 | S610: 0 | T610: 0 | U610: 0 | V610: 0 | W610: 0 | X610: 0 | Y610: 0 | Z610: 0 | AA610: 0 | AB610: 0 | AC610: 0 | AD610: 0 | AE610: 0 | AF610: 0 | AG610: 0 | AH610: 0 | AI610: 0 | AJ610: 0 | AK610: 0 | AL610: 0 | AM610: 0 | AN610: 0 | AO610: 0 | AP610: 0.0089722284 | AQ610: 0.018390203 | AR610: 0.028250636 | AS610: 0.038549502 | AT610: 0.049282042 | AU610: 0.060442766 | AV610: 0.072025465 | AW610: 0.084023208 | AX610: 0.096428362 | AY610: 0.10923259 | AZ610: 0.12242688 | BA610: 0.13600154 | BB610: 0.14994622 | BC610: 0.16424993 | BD610: 0.17890105 | BE610: 0.19388735 | BF610: 0.20919603 | BG610: 0.22481369 | BH610: 0.24072641 | BI610: 0.25691974 | BJ610: 0.27337873 | BK610: 0.29008795 | BL610: 0.30703153 | BM610: 0.32419316 | BN610: 0.34155617 | BO610: 0.35910348 | BP610: 0.37681771 | BQ610: 0.39468116 | BR610: 0.41267583 | BS610: 0.43078352 | BT610: 0.44898578 | BU610: 0.46726399 | BV610: 0.48559938 | BW610: 0.50397306 | BX610: 0.52236606 | BY610: 0.54075937 | BZ610: 0.55913393 | CA610: 0.57747073 | CB610: 0.5957508 | CC610: 0.61395523 | CD610: 0.63206526 | CE610: 1 | CF610: 1 | CG610: 1 | CH610: 1 | CI610: 1 | CJ610: 1 | CK610: 1 | CL610: 1 | CM610: 1 | CN610: 1 | CO610: 1 | CP610: 1 | CQ610: 1 | CR610: 1 | CS610: 1 | CT610: 1 | CU610: 1 | CV610: 1 | CW610: 1 | CX610: 1 | CY610: 1 | CZ610: 1 | DA610: 1 | DB610: 1 | DC610: 1 | DD610: 1 | DE610: 1 | DF610: 1 | DG610: 1 | DH610: 1 | DI610: 1 | DJ610: 1 | DK610: 1 | DL610: 1 | DM610: 1 | DN610: 1 | DO610: 1 | DP610: 1 | DQ610: 1 | DR610: 1
A611: 1.1 | B611: 0 | C611: 0 | D611: 0 | E611: 0 | F611: 0 | G611: 0 | H611: 0 | I611: 0 | J611: 0 | K611: 0 | L611: 0 | M611: 0 | N611: 0 | O611: 0 | P611: 0 | Q611: 0 | R611: 0 | S611: 0 | T611: 0 | U611: 0 | V611: 0 | W611: 0 | X611: 0 | Y611: 0 | Z611: 0 | AA611: 0 | AB611: 0 | AC611: 0 | AD611: 0 | AE611: 0 | AF611: 0 | AG611: 0 | AH611: 0 | AI611: 0 | AJ611: 0 | AK611: 0 | AL611: 0 | AM611: 0 | AN611: 0 | AO611: 0.0085399384 | AP611: 0.01751482 | AQ611: 0.026922043 | AR611: 0.03675829 | AS611: 0.047019538 | AT611: 0.057701053 | AU611: 0.068797398 | AV611: 0.080302442 | AW611: 0.092209362 | AX611: 0.10451065 | AY611: 0.11719814 | AZ611: 0.13026299 | BA611: 0.14369572 | BB611: 0.15748622 | BC611: 0.17162374 | BD611: 0.18609696 | BE611: 0.20089395 | BF611: 0.21600223 | BG611: 0.23140876 | BH611: 0.24709998 | BI611: 0.26306185 | BJ611: 0.27927981 | BK611: 0.29573888 | BL611: 0.31242362 | BM611: 0.3293182 | BN611: 0.34640643 | BO611: 0.36367172 | BP611: 0.38109721 | BQ611: 0.39866572 | BR611: 0.41635979 | BS611: 0.43416177 | BT611: 0.45205376 | BU611: 0.47001772 | BV611: 0.48803544 | BW611: 0.50608863 | BX611: 0.52415889 | BY611: 0.54222779 | BZ611: 0.5602769 | CA611: 0.57828777 | CB611: 0.59624203 | CC611: 0.61412139 | CD611: 0.63190765 | CE611: 0.64958278 | CF611: 1 | CG611: 1 | CH611: 1 | CI611: 1 | CJ611: 1 | CK611: 1 | CL611: 1 | CM611: 1 | CN611: 1 | CO611: 1 | CP611: 1 | CQ611: 1 | CR611: 1 | CS611: 1 | CT611: 1 | CU611: 1 | CV611: 1 | CW611: 1 | CX611: 1 | CY611: 1 | CZ611: 1 | DA611: 1 | DB611: 1 | DC611: 1 | DD611: 1 | DE611: 1 | DF611: 1 | DG611: 1 | DH611: 1 | DI611: 1 | DJ611: 1 | DK611: 1 | DL611: 1 | DM611: 1 | DN611: 1 | DO611: 1 | DP611: 1 | DQ611: 1 | DR611: 1
A612: 1.15 | B612: 0 | C612: 0 | D612: 0 | E612: 0 | F612: 0 | G612: 0 | H612: 0 | I612: 0 | J612: 0 | K612: 0 | L612: 0 | M612: 0 | N612: 0 | O612: 0 | P612: 0 | Q612: 0 | R612: 0 | S612: 0 | T612: 0 | U612: 0 | V612: 0 | W612: 0 | X612: 0 | Y612: 0 | Z612: 0 | AA612: 0 | AB612: 0 | AC612: 0 | AD612: 0 | AE612: 0 | AF612: 0 | AG612: 0 | AH612: 0 | AI612: 0 | AJ612: 0 | AK612: 0 | AL612: 0 | AM612: 0 | AN612: 0.0081284754 | AO612: 0.016681098 | AP612: 0.025655903 | AQ612: 0.035050242 | AR612: 0.044860775 | AS612: 0.055083481 | AT612: 0.065713653 | AU612: 0.07674591 | AV612: 0.088174196 | AW612: 0.099991794 | AX612: 0.11219133 | AY612: 0.12476478 | AZ612: 0.13770348 | BA612: 0.15099816 | BB612: 0.16463893 | BC612: 0.17861529 | BD612: 0.1929162 | BE612: 0.20753001 | BF612: 0.22244456 | BG612: 0.23764715 | BH612: 0.25312458 | BI612: 0.26886317 | BJ612: 0.28484877 | BK612: 0.30106681 | BL612: 0.31750228 | BM612: 0.3341398 | BN612: 0.35096363 | BO612: 0.36795768 | BP612: 0.38510556 | BQ612: 0.40239059 | BR612: 0.41979586 | BS612: 0.4373042 | BT612: 0.45489827 | BU612: 0.47256056 | BV612: 0.49027343 | BW612: 0.50801912 | BX612: 0.52577981 | BY612: 0.54353764 | BZ612: 0.56127472 | CA612: 0.57897319 | CB612: 0.59661524 | CC612: 0.61418315 | CD612: 0.63165929 | CE612: 0.64902618 | CF612: 0.66626653 | CG612: 1 | CH612: 1 | CI612: 1 | CJ612: 1 | CK612: 1 | CL612: 1 | CM612: 1 | CN612: 1 | CO612: 1 | CP612: 1 | CQ612: 1 | CR612: 1 | CS612: 1 | CT612: 1 | CU612: 1 | CV612: 1 | CW612: 1 | CX612: 1 | CY612: 1 | CZ612: 1 | DA612: 1 | DB612: 1 | DC612: 1 | DD612: 1 | DE612: 1 | DF612: 1 | DG612: 1 | DH612: 1 | DI612: 1 | DJ612: 1 | DK612: 1 | DL612: 1 | DM612: 1 | DN612: 1 | DO612: 1 | DP612: 1 | DQ612: 1 | DR612: 1
... A709: 6 | B709: 0.067731439 | C709: 0.070832477 | D709: 0.074025938 | E709: 0.077312722 | F709: 0.080693677 | G709: 0.084169597 | H709: 0.087741222 | I709: 0.091409234 | J709: 0.095174256 | K709: 0.099036852 | L709: 0.10299752 | M709: 0.10705671 | N709: 0.11121479 | O709: 0.11547206 | P709: 0.11982878 | Q709: 0.12428511 | R709: 0.12884117 | S709: 0.13349699 | T709: 0.13825253 | U709: 0.14310768 | V709: 0.14806228 | W709: 0.15311606 | X709: 0.1582687 | Y709: 0.1635198 | Z709: 0.16886889 | AA709: 0.1743154 | AB709: 0.17985873 | AC709: 0.18549816 | AD709: 0.19123291 | AE709: 0.19706214 | AF709: 0.20298491 | AG709: 0.20900021 | AH709: 0.21510698 | AI709: 0.22130404 | AJ709: 0.22759016 | AK709: 0.23396405 | AL709: 0.24042432 | AM709: 0.24696952 | AN709: 0.25359813 | AO709: 0.26030854 | AP709: 0.26709908 | AQ709: 0.27396803 | AR709: 0.28091358 | AS709: 0.28793385 | AT709: 0.29502691 | AU709: 0.30219074 | AV709: 0.30942329 | AW709: 0.31672243 | AX709: 0.32408596 | AY709: 0.33151163 | AZ709: 0.33899715 | BA709: 0.34654015 | BB709: 0.35413823 | BC709: 0.36178891 | BD709: 0.36948968 | BE709: 0.37723799 | BF709: 0.38503123 | BG709: 0.39286674 | BH709: 0.40074185 | BI709: 0.40865382 | BJ709: 0.4165999 | BK709: 0.42457728 | BL709: 0.43258315 | BM709: 0.44061463 | BN709: 0.44866886 | BO709: 0.45674293 | BP709: 0.4648339 | BQ709: 0.47293884 | BR709: 0.48105479 | BS709: 0.48917876 | BT709: 0.49730779 | BU709: 0.50543887 | BV709: 0.51356902 | BW709: 0.52169522 | BX709: 0.52981449 | BY709: 0.53792383 | BZ709: 0.54602025 | CA709: 0.55410077 | CB709: 0.56216242 | CC709: 0.57020224 | CD709: 0.57821729 | CE709: 0.58620466 | CF709: 0.59416145 | CG709: 0.60208478 | CH709: 0.60997181 | CI709: 0.61781972 | CJ709: 0.62562572 | CK709: 0.63338706 | CL709: 0.64110102 | CM709: 0.64876494 | CN709: 0.65637618 | CO709: 0.66393214 | CP709: 0.67143029 | CQ709: 0.67886812 | CR709: 0.68624318 | CS709: 0.69355309 | CT709: 0.7007955 | CU709: 0.70796813 | CV709: 0.71506874 | CW709: 0.72209517 | CX709: 0.72904532 | CY709: 0.73591713 | CZ709: 0.74270862 | DA709: 0.74941788 | DB709: 0.75604306 | DC709: 0.76258238 | DD709: 0.76903412 | DE709: 0.77539664 | DF709: 0.78166837 | DG709: 0.78784782 | DH709: 0.79393355 | DI709: 0.79992422 | DJ709: 0.80581854 | DK709: 0.81161531 | DL709: 0.8173134 | DM709: 0.82291176 | DN709: 0.82840941 | DO709: 0.83380546 | DP709: 0.83909907 | DQ709: 0.8442895 | DR709: 0.84937607

Sheet Pontos
A1: resultado\palpite | B1: 0x0 | C1: 0x1 | D1: 0x2 | E1: 0x3 | F1: 0x4 | G1: 0x5 | H1: 0x6 | I1: 1x0 | J1: 1x1 | K1: 1x2 | L1: 1x3 | M1: 1x4 | N1: 1x5 | O1: 1x6 | P1: 2x0 | Q1: 2x1 | R1: 2x2 | S1: 2x3 | T1: 2x4 | U1: 2x5 | V1: 2x6 | W1: 3x0 | X1: 3x1 | Y1: 3x2 | Z1: 3x3 | AA1: 3x4 | AB1: 3x5 | AC1: 3x6 | AD1: 4x0 | AE1: 4x1 | AF1: 4x2 | AG1: 4x3 | AH1: 4x4 | AI1: 4x5 | AJ1: 4x6 | AK1: 5x0 | AL1: 5x1 | AM1: 5x2 | AN1: 5x3 | AO1: 5x4 | AP1: 5x5 | AQ1: 5x6 | AR1: 6x0 | AS1: 6x1 | AT1: 6x2 | AU1: 6x3 | AV1: 6x4 | AW1: 6x5 | AX1: 6x6
A2: 0x0 | B2: 10 | C2: 0 | D2: 0 | E2: 0 | F2: 0 | G2: 0 | H2: 0 | I2: 0 | J2: 5 | K2: 0 | L2: 0 | M2: 0 | N2: 0 | O2: 0 | P2: 0 | Q2: 0 | R2: 5 | S2: 0 | T2: 0 | U2: 0 | V2: 0 | W2: 0 | X2: 0 | Y2: 0 | Z2: 5 | AA2: 0 | AB2: 0 | AC2: 0 | AD2: 0 | AE2: 0 | AF2: 0 | AG2: 0 | AH2: 5 | AI2: 0 | AJ2: 0 | AK2: 0 | AL2: 0 | AM2: 0 | AN2: 0 | AO2: 0 | AP2: 5 | AQ2: 0 | AR2: 0 | AS2: 0 | AT2: 0 | AU2: 0 | AV2: 0 | AW2: 0 | AX2: 5
A3: 0x1 | B3: 0 | C3: 10 | D3: 6 | E3: 6 | F3: 6 | G3: 6 | H3: 6 | I3: -2 | J3: 0 | K3: 6 | L3: 5 | M3: 5 | N3: 5 | O3: 5 | P3: 0 | Q3: 0 | R3: 0 | S3: 6 | T3: 5 | U3: 5 | V3: 5 | W3: 0 | X3: 0 | Y3: 0 | Z3: 0 | AA3: 6 | AB3: 5 | AC3: 5 | AD3: 0 | AE3: 0 | AF3: 0 | AG3: 0 | AH3: 0 | AI3: 6 | AJ3: 5 | AK3: 0 | AL3: 0 | AM3: 0 | AN3: 0 | AO3: 0 | AP3: 0 | AQ3: 6 | AR3: 0 | AS3: 0 | AT3: 0 | AU3: 0 | AV3: 0 | AW3: 0 | AX3: 0
A4: 0x2 | B4: 0 | C4: 6 | D4: 10 | E4: 6 | F4: 6 | G4: 6 | H4: 6 | I4: 0 | J4: 0 | K4: 6 | L4: 6 | M4: 5 | N4: 5 | O4: 5 | P4: -2 | Q4: 0 | R4: 0 | S4: 5 | T4: 6 | U4: 5 | V4: 5 | W4: 0 | X4: 0 | Y4: 0 | Z4: 0 | AA4: 5 | AB4: 6 | AC4: 5 | AD4: 0 | AE4: 0 | AF4: 0 | AG4: 0 | AH4: 0 | AI4: 5 | AJ4: 6 | AK4: 0 | AL4: 0 | AM4: 0 | AN4: 0 | AO4: 0 | AP4: 0 | AQ4: 5 | AR4: 0 | AS4: 0 | AT4: 0 | AU4: 0 | AV4: 0 | AW4: 0 | AX4: 0
A5: 0x3 | B5: 0 | C5: 6 | D5: 6 | E5: 10 | F5: 6 | G5: 6 | H5: 6 | I5: 0 | J5: 0 | K5: 5 | L5: 6 | M5: 6 | N5: 5 | O5: 5 | P5: 0 | Q5: 0 | R5: 0 | S5: 6 | T5: 5 | U5: 6 | V5: 5 | W5: -2 | X5: 0 | Y5: 0 | Z5: 0 | AA5: 5 | AB5: 5 | AC5: 6 | AD5: 0 | AE5: 0 | AF5: 0 | AG5: 0 | AH5: 0 | AI5: 5 | AJ5: 5 | AK5: 0 | AL5: 0 | AM5: 0 | AN5: 0 | AO5: 0 | AP5: 0 | AQ5: 5 | AR5: 0 | AS5: 0 | AT5: 0 | AU5: 0 | AV5: 0 | AW5: 0 | AX5: 0
A6: 0x4 | B6: 0 | C6: 6 | D6: 6 | E6: 6 | F6: 10 | G6: 6 | H6: 6 | I6: 0 | J6: 0 | K6: 5 | L6: 5 | M6: 6 | N6: 6 | O6: 5 | P6: 0 | Q6: 0 | R6: 0 | S6: 5 | T6: 6 | U6: 5 | V6: 6 | W6: 0 | X6: 0 | Y6: 0 | Z6: 0 | AA6: 6 | AB6: 5 | AC6: 5 | AD6: -2 | AE6: 0 | AF6: 0 | AG6: 0 | AH6: 0 | AI6: 5 | AJ6: 5 | AK6: 0 | AL6: 0 | AM6: 0 | AN6: 0 | AO6: 0 | AP6: 0 | AQ6: 5 | AR6: 0 | AS6: 0 | AT6: 0 | AU6: 0 | AV6: 0 | AW6: 0 | AX6: 0
A7: 0x5 | B7: 0 | C7: 6 | D7: 6 | E7: 6 | F7: 6 | G7: 10 | H7: 6 | I7: 0 | J7: 0 | K7: 5 | L7: 5 | M7: 5 | N7: 6 | O7: 6 | P7: 0 | Q7: 0 | R7: 0 | S7: 5 | T7: 5 | U7: 6 | V7: 5 | W7: 0 | X7: 0 | Y7: 0 | Z7: 0 | AA7: 5 | AB7: 6 | AC7: 5 | AD7: 0 | AE7: 0 | AF7: 0 | AG7: 0 | AH7: 0 | AI7: 6 | AJ7: 5 | AK7: -2 | AL7: 0 | AM7: 0 | AN7: 0 | AO7: 0 | AP7: 0 | AQ7: 5 | AR7: 0 | AS7: 0 | AT7: 0 | AU7: 0 | AV7: 0 | AW7: 0 | AX7: 0
A8: 0x6 | B8: 0 | C8: 6 | D8: 6 | E8: 6 | F8: 6 | G8: 6 | H8: 10 | I8: 0 | J8: 0 | K8: 5 | L8: 5 | M8: 5 | N8: 5 | O8: 6 | P8: 0 | Q8: 0 | R8: 0 | S8: 5 | T8: 5 | U8: 5 | V8: 6 | W8: 0 | X8: 0 | Y8: 0 | Z8: 0 | AA8: 5 | AB8: 5 | AC8: 6 | AD8: 0 | AE8: 0 | AF8: 0 | AG8: 0 | AH8: 0 | AI8: 5 | AJ8: 6 | AK8: 0 | AL8: 0 | AM8: 0 | AN8: 0 | AO8: 0 | AP8: 0 | AQ8: 6 | AR8: -2 | AS8: 0 | AT8: 0 | AU8: 0 | AV8: 0 | AW8: 0 | AX8: 0
A9: 1x0 | B9: 0 | C9: -2 | D9: 0 | E9: 0 | F9: 0 | G9: 0 | H9: 0 | I9: 10 | J9: 0 | K9: 0 | L9: 0 | M9: 0 | N9: 0 | O9: 0 | P9: 6 | Q9: 6 | R9: 0 | S9: 0 | T9: 0 | U9: 0 | V9: 0 | W9: 6 | X9: 5 | Y9: 6 | Z9: 0 | AA9: 0 | AB9: 0 | AC9: 0 | AD9: 6 | AE9: 5 | AF9: 5 | AG9: 6 | AH9: 0 | AI9: 0 | AJ9: 0 | AK9: 6 | AL9: 5 | AM9: 5 | AN9: 5 | AO9: 6 | AP9: 0 | AQ9: 0 | AR9: 6 | AS9: 5 | AT9: 5 | AU9: 5 | AV9: 5 | AW9: 6 | AX9: 0
A10: 1x1 | B10: 5 | C10: 0 | D10: 0 | E10: 0 | F10: 0 | G10: 0 | H10: 0 | I10: 0 | J10: 10 | K10: 0 | L10: 0 | M10: 0 | N10: 0 | O10: 0 | P10: 0 | Q10: 0 | R10: 5 | S10: 0 | T10: 0 | U10: 0 | V10: 0 | W10: 0 | X10: 0 | Y10: 0 | Z10: 5 | AA10: 0 | AB10: 0 | AC10: 0 | AD10: 0 | AE10: 0 | AF10: 0 | AG10: 0 | AH10: 5 | AI10: 0 | AJ10: 0 | AK10: 0 | AL10: 0 | AM10: 0 | AN10: 0 | AO10: 0 | AP10: 5 | AQ10: 0 | AR10: 0 | AS10: 0 | AT10: 0 | AU10: 0 | AV10: 0 | AW10: 0 | AX10: 5
A11: 1x2 | B11: 0 | C11: 6 | D11: 6 | E11: 5 | F11: 5 | G11: 5 | H11: 5 | I11: 0 | J11: 0 | K11: 10 | L11: 6 | M11: 6 | N11: 6 | O11: 6 | P11: 0 | Q11: -2 | R11: 0 | S11: 6 | T11: 5 | U11: 5 | V11: 5 | W11: 0 | X11: 0 | Y11: 0 | Z11: 0 | AA11: 6 | AB11: 5 | AC11: 5 | AD11: 0 | AE11: 0 | AF11: 0 | AG11: 0 | AH11: 0 | AI11: 6 | AJ11: 5 | AK11: 0 | AL11: 0 | AM11: 0 | AN11: 0 | AO11: 0 | AP11: 0 | AQ11: 6 | AR11: 0 | AS11: 0 | AT11: 0 | AU11: 0 | AV11: 0 | AW11: 0 | AX11: 0
A12: 1x3 | B12: 0 | C12: 5 | D12: 6 | E12: 6 | F12: 5 | G12: 5 | H12: 5 | I12: 0 | J12: 0 | K12: 6 | L12: 10 | M12: 6 | N12: 6 | O12: 6 | P12: 0 | Q12: 0 | R12: 0 | S12: 6 | T12: 6 | U12: 5 | V12: 5 | W12: 0 | X12: -2 | Y12: 0 | Z12: 0 | AA12: 5 | AB12: 6 | AC12: 5 | AD12: 0 | AE12: 0 | AF12: 0 | AG12: 0 | AH12: 0 | AI12: 5 | AJ12: 6 | AK12: 0 | AL12: 0 | AM12: 0 | AN12: 0 | AO12: 0 | AP12: 0 | AQ12: 5 | AR12: 0 | AS12: 0 | AT12: 0 | AU12: 0 | AV12: 0 | AW12: 0 | AX12: 0
A13: 1x4 | B13: 0 | C13: 5 | D13: 5 | E13: 6 | F13: 6 | G13: 5 | H13: 5 | I13: 0 | J13: 0 | K13: 6 | L13: 6 | M13: 10 | N13: 6 | O13: 6 | P13: 0 | Q13: 0 | R13: 0 | S13: 5 | T13: 6 | U13: 6 | V13: 5 | W13: 0 | X13: 0 | Y13: 0 | Z13: 0 | AA13: 6 | AB13: 5 | AC13: 6 | AD13: 0 | AE13: -2 | AF13: 0 | AG13: 0 | AH13: 0 | AI13: 5 | AJ13: 5 | AK13: 0 | AL13: 0 | AM13: 0 | AN13: 0 | AO13: 0 | AP13: 0 | AQ13: 5 | AR13: 0 | AS13: 0 | AT13: 0 | AU13: 0 | AV13: 0 | AW13: 0 | AX13: 0
... A50: 6x6 | B50: 5 | C50: 0 | D50: 0 | E50: 0 | F50: 0 | G50: 0 | H50: 0 | I50: 0 | J50: 5 | K50: 0 | L50: 0 | M50: 0 | N50: 0 | O50: 0 | P50: 0 | Q50: 0 | R50: 5 | S50: 0 | T50: 0 | U50: 0 | V50: 0 | W50: 0 | X50: 0 | Y50: 0 | Z50: 5 | AA50: 0 | AB50: 0 | AC50: 0 | AD50: 0 | AE50: 0 | AF50: 0 | AG50: 0 | AH50: 5 | AI50: 0 | AJ50: 0 | AK50: 0 | AL50: 0 | AM50: 0 | AN50: 0 | AO50: 0 | AP50: 5 | AQ50: 0 | AR50: 0 | AS50: 0 | AT50: 0 | AU50: 0 | AV50: 0 | AW50: 0 | AX50: 10

Sheet Jogo
H1: 0 | I1: 1 | J1: 2 | K1: 3 | L1: 4 | M1: 5 | N1: 6
A2: Odd Over 2.5 | B2: 2.21 | C2: Flag estreia | D2: 1 | E2: Modal pelotão (ex 2x1) | F2: 2x1 | G2: 0 | H2: =_xlfn.POISSON.DIST($G2,$B$18,FALSE)*_xlfn.POISSON.DIST(H$1,$B$19,FALSE)*Config!$B$3 | I2: =_xlfn.POISSON.DIST($G2,$B$18,FALSE)*_xlfn.POISSON.DIST(I$1,$B$19,FALSE) | J2: =_xlfn.POISSON.DIST($G2,$B$18,FALSE)*_xlfn.POISSON.DIST(J$1,$B$19,FALSE) | K2: =_xlfn.POISSON.DIST($G2,$B$18,FALSE)*_xlfn.POISSON.DIST(K$1,$B$19,FALSE) | L2: =_xlfn.POISSON.DIST($G2,$B$18,FALSE)*_xlfn.POISSON.DIST(L$1,$B$19,FALSE) | M2: =_xlfn.POISSON.DIST($G2,$B$18,FALSE)*_xlfn.POISSON.DIST(M$1,$B$19,FALSE) | N2: =_xlfn.POISSON.DIST($G2,$B$18,FALSE)*_xlfn.POISSON.DIST(N$1,$B$19,FALSE) | P2: EV 1º | Q2: =LARGE($K$13:$K$61,1) | R2: =INDEX($G$13:$G$61,MATCH(Q2,$K$13:$K$61,0))
A3: Odd Under 2.5 | B3: 1.67 | C3: Flag dead rubber | D3: 0 | E3: Estado (LIDER/PELOTAO/CACADOR) | F3: PELOTAO | G3: 1 | H3: =_xlfn.POISSON.DIST($G3,$B$18,FALSE)*_xlfn.POISSON.DIST(H$1,$B$19,FALSE) | I3: =_xlfn.POISSON.DIST($G3,$B$18,FALSE)*_xlfn.POISSON.DIST(I$1,$B$19,FALSE)*Config!$B$3 | J3: =_xlfn.POISSON.DIST($G3,$B$18,FALSE)*_xlfn.POISSON.DIST(J$1,$B$19,FALSE) | K3: =_xlfn.POISSON.DIST($G3,$B$18,FALSE)*_xlfn.POISSON.DIST(K$1,$B$19,FALSE) | L3: =_xlfn.POISSON.DIST($G3,$B$18,FALSE)*_xlfn.POISSON.DIST(L$1,$B$19,FALSE) | M3: =_xlfn.POISSON.DIST($G3,$B$18,FALSE)*_xlfn.POISSON.DIST(M$1,$B$19,FALSE) | N3: =_xlfn.POISSON.DIST($G3,$B$18,FALSE)*_xlfn.POISSON.DIST(N$1,$B$19,FALSE) | P3: EV 2º | Q3: =LARGE($K$13:$K$61,2) | R3: =INDEX($G$13:$G$61,MATCH(Q3,$K$13:$K$61,0))
A4: Odd Casa | B4: 2.61 | C4: Flag clima extremo | D4: 0 | G4: 2 | H4: =_xlfn.POISSON.DIST($G4,$B$18,FALSE)*_xlfn.POISSON.DIST(H$1,$B$19,FALSE) | I4: =_xlfn.POISSON.DIST($G4,$B$18,FALSE)*_xlfn.POISSON.DIST(I$1,$B$19,FALSE) | J4: =_xlfn.POISSON.DIST($G4,$B$18,FALSE)*_xlfn.POISSON.DIST(J$1,$B$19,FALSE) | K4: =_xlfn.POISSON.DIST($G4,$B$18,FALSE)*_xlfn.POISSON.DIST(K$1,$B$19,FALSE) | L4: =_xlfn.POISSON.DIST($G4,$B$18,FALSE)*_xlfn.POISSON.DIST(L$1,$B$19,FALSE) | M4: =_xlfn.POISSON.DIST($G4,$B$18,FALSE)*_xlfn.POISSON.DIST(M$1,$B$19,FALSE) | N4: =_xlfn.POISSON.DIST($G4,$B$18,FALSE)*_xlfn.POISSON.DIST(N$1,$B$19,FALSE) | P4: EV 3º | Q4: =LARGE($K$13:$K$61,3) | R4: =INDEX($G$13:$G$61,MATCH(Q4,$K$13:$K$61,0))
A5: Odd Empate | B5: 3.05 | C5: Flag risco rotação | D5: 0 | E5: S_elo (aba Elo, opcional) | G5: 3 | H5: =_xlfn.POISSON.DIST($G5,$B$18,FALSE)*_xlfn.POISSON.DIST(H$1,$B$19,FALSE) | I5: =_xlfn.POISSON.DIST($G5,$B$18,FALSE)*_xlfn.POISSON.DIST(I$1,$B$19,FALSE) | J5: =_xlfn.POISSON.DIST($G5,$B$18,FALSE)*_xlfn.POISSON.DIST(J$1,$B$19,FALSE) | K5: =_xlfn.POISSON.DIST($G5,$B$18,FALSE)*_xlfn.POISSON.DIST(K$1,$B$19,FALSE) | L5: =_xlfn.POISSON.DIST($G5,$B$18,FALSE)*_xlfn.POISSON.DIST(L$1,$B$19,FALSE) | M5: =_xlfn.POISSON.DIST($G5,$B$18,FALSE)*_xlfn.POISSON.DIST(M$1,$B$19,FALSE) | N5: =_xlfn.POISSON.DIST($G5,$B$18,FALSE)*_xlfn.POISSON.DIST(N$1,$B$19,FALSE) | P5: margem | Q5: =Q2-Q3
A6: Odd Fora | B6: 3 | C6: Flag dados ralos | D6: 0 | G6: 4 | H6: =_xlfn.POISSON.DIST($G6,$B$18,FALSE)*_xlfn.POISSON.DIST(H$1,$B$19,FALSE) | I6: =_xlfn.POISSON.DIST($G6,$B$18,FALSE)*_xlfn.POISSON.DIST(I$1,$B$19,FALSE) | J6: =_xlfn.POISSON.DIST($G6,$B$18,FALSE)*_xlfn.POISSON.DIST(J$1,$B$19,FALSE) | K6: =_xlfn.POISSON.DIST($G6,$B$18,FALSE)*_xlfn.POISSON.DIST(K$1,$B$19,FALSE) | L6: =_xlfn.POISSON.DIST($G6,$B$18,FALSE)*_xlfn.POISSON.DIST(L$1,$B$19,FALSE) | M6: =_xlfn.POISSON.DIST($G6,$B$18,FALSE)*_xlfn.POISSON.DIST(M$1,$B$19,FALSE) | N6: =_xlfn.POISSON.DIST($G6,$B$18,FALSE)*_xlfn.POISSON.DIST(N$1,$B$19,FALSE) | P6: decisão | Q6: =IF(Q5<=Config!$B$4,"FRONTEIRA: aplicar POLITICA.md vs modal F2","OK: cravar o 1º")
A7: Fase (1 grupo/2 mata/3 final) | B7: 1 | G7: 5 | H7: =_xlfn.POISSON.DIST($G7,$B$18,FALSE)*_xlfn.POISSON.DIST(H$1,$B$19,FALSE) | I7: =_xlfn.POISSON.DIST($G7,$B$18,FALSE)*_xlfn.POISSON.DIST(I$1,$B$19,FALSE) | J7: =_xlfn.POISSON.DIST($G7,$B$18,FALSE)*_xlfn.POISSON.DIST(J$1,$B$19,FALSE) | K7: =_xlfn.POISSON.DIST($G7,$B$18,FALSE)*_xlfn.POISSON.DIST(K$1,$B$19,FALSE) | L7: =_xlfn.POISSON.DIST($G7,$B$18,FALSE)*_xlfn.POISSON.DIST(L$1,$B$19,FALSE) | M7: =_xlfn.POISSON.DIST($G7,$B$18,FALSE)*_xlfn.POISSON.DIST(M$1,$B$19,FALSE) | N7: =_xlfn.POISSON.DIST($G7,$B$18,FALSE)*_xlfn.POISSON.DIST(N$1,$B$19,FALSE) | P7: tripwire | Q7: =IF($F$5="","sem elo",IF(ABS(B15-$F$5)>Config!$B$7,"⚠ CONFERIR LINHA DIGITADA","ok"))
A8: Δλ exceção CASA (POLITICA.md) | B8: 0 | G8: 6 | H8: =_xlfn.POISSON.DIST($G8,$B$18,FALSE)*_xlfn.POISSON.DIST(H$1,$B$19,FALSE) | I8: =_xlfn.POISSON.DIST($G8,$B$18,FALSE)*_xlfn.POISSON.DIST(I$1,$B$19,FALSE) | J8: =_xlfn.POISSON.DIST($G8,$B$18,FALSE)*_xlfn.POISSON.DIST(J$1,$B$19,FALSE) | K8: =_xlfn.POISSON.DIST($G8,$B$18,FALSE)*_xlfn.POISSON.DIST(K$1,$B$19,FALSE) | L8: =_xlfn.POISSON.DIST($G8,$B$18,FALSE)*_xlfn.POISSON.DIST(L$1,$B$19,FALSE) | M8: =_xlfn.POISSON.DIST($G8,$B$18,FALSE)*_xlfn.POISSON.DIST(M$1,$B$19,FALSE) | N8: =_xlfn.POISSON.DIST($G8,$B$18,FALSE)*_xlfn.POISSON.DIST(N$1,$B$19,FALSE)
A9: Δλ exceção FORA | B9: 0
O10: soma grid | P10: =SUM(H2:N8)
A11: p_over | B11: =(1/B2)/((1/B2)+(1/B3))
A12: p_casa | B12: =(1/B4)/((1/B4)+(1/B5)+(1/B6)) | G12: placar | H12: ph | I12: pa | J12: P | K12: EV | L12: P_exato | M12: P_invertido
A13: lambda_total | B13: =INDEX(Tabelas!$A$2:$A$582,MATCH(B11,Tabelas!$B$2:$B$582,1)) | G13: 0x0 | H13: 0 | I13: 0 | J13: =((1-$B$20)*INDEX($H$2:$N$8,H13+1,I13+1)/$P$10)+$B$20/49 | K13: =SUMPRODUCT(INDEX(Pontos!$B$2:$AX$50,0,1),$J$13:$J$61)*$B$7 | L13: =J13 | M13: =IF(H13=I13,0,INDEX($J$13:$J$61,I13*7+H13+1))
A14: linha_T2 | B14: =MATCH(B13,Tabelas!$A$601:$A$709,1) | G14: 0x1 | H14: 0 | I14: 1 | J14: =((1-$B$20)*INDEX($H$2:$N$8,H14+1,I14+1)/$P$10)+$B$20/49 | K14: =SUMPRODUCT(INDEX(Pontos!$B$2:$AX$50,0,2),$J$13:$J$61)*$B$7 | L14: =J14 | M14: =IF(H14=I14,0,INDEX($J$13:$J$61,I14*7+H14+1))
A15: S (supremacia) | B15: =INDEX(Tabelas!$B$600:$DR$600,MATCH(B12,INDEX(Tabelas!$B$601:$DR$709,B14,0),1)) | G15: 0x2 | H15: 0 | I15: 2 | J15: =((1-$B$20)*INDEX($H$2:$N$8,H15+1,I15+1)/$P$10)+$B$20/49 | K15: =SUMPRODUCT(INDEX(Pontos!$B$2:$AX$50,0,3),$J$13:$J$61)*$B$7 | L15: =J15 | M15: =IF(H15=I15,0,INDEX($J$13:$J$61,I15*7+H15+1))
A16: lambda_casa_mercado | B16: =(B13+B15)/2 | G16: 0x3 | H16: 0 | I16: 3 | J16: =((1-$B$20)*INDEX($H$2:$N$8,H16+1,I16+1)/$P$10)+$B$20/49 | K16: =SUMPRODUCT(INDEX(Pontos!$B$2:$AX$50,0,4),$J$13:$J$61)*$B$7 | L16: =J16 | M16: =IF(H16=I16,0,INDEX($J$13:$J$61,I16*7+H16+1))
A17: lambda_fora_mercado | B17: =(B13-B15)/2 | G17: 0x4 | H17: 0 | I17: 4 | J17: =((1-$B$20)*INDEX($H$2:$N$8,H17+1,I17+1)/$P$10)+$B$20/49 | K17: =SUMPRODUCT(INDEX(Pontos!$B$2:$AX$50,0,5),$J$13:$J$61)*$B$7 | L17: =J17 | M17: =IF(H17=I17,0,INDEX($J$13:$J$61,I17*7+H17+1))
A18: lambda_casa_final | B18: =B16*(1+Config!$B$2)+MAX(-Config!$B$6*B16,MIN(Config!$B$6*B16,B8)) | G18: 0x5 | H18: 0 | I18: 5 | J18: =((1-$B$20)*INDEX($H$2:$N$8,H18+1,I18+1)/$P$10)+$B$20/49 | K18: =SUMPRODUCT(INDEX(Pontos!$B$2:$AX$50,0,6),$J$13:$J$61)*$B$7 | L18: =J18 | M18: =IF(H18=I18,0,INDEX($J$13:$J$61,I18*7+H18+1))
A19: lambda_fora_final | B19: =B17*(1+Config!$B$2)+MAX(-Config!$B$6*B17,MIN(Config!$B$6*B17,B9)) | G19: 0x6 | H19: 0 | I19: 6 | J19: =((1-$B$20)*INDEX($H$2:$N$8,H19+1,I19+1)/$P$10)+$B$20/49 | K19: =SUMPRODUCT(INDEX(Pontos!$B$2:$AX$50,0,7),$J$13:$J$61)*$B$7 | L19: =J19 | M19: =IF(H19=I19,0,INDEX($J$13:$J$61,I19*7+H19+1))
A20: w achatamento | B20: =MIN(0.25,Config!$B$5*SUM(D2:D6)) | G20: 1x0 | H20: 1 | I20: 0 | J20: =((1-$B$20)*INDEX($H$2:$N$8,H20+1,I20+1)/$P$10)+$B$20/49 | K20: =SUMPRODUCT(INDEX(Pontos!$B$2:$AX$50,0,8),$J$13:$J$61)*$B$7 | L20: =J20 | M20: =IF(H20=I20,0,INDEX($J$13:$J$61,I20*7+H20+1))
G21: 1x1 | H21: 1 | I21: 1 | J21: =((1-$B$20)*INDEX($H$2:$N$8,H21+1,I21+1)/$P$10)+$B$20/49 | K21: =SUMPRODUCT(INDEX(Pontos!$B$2:$AX$50,0,9),$J$13:$J$61)*$B$7 | L21: =J21 | M21: =IF(H21=I21,0,INDEX($J$13:$J$61,I21*7+H21+1))
G22: 1x2 | H22: 1 | I22: 2 | J22: =((1-$B$20)*INDEX($H$2:$N$8,H22+1,I22+1)/$P$10)+$B$20/49 | K22: =SUMPRODUCT(INDEX(Pontos!$B$2:$AX$50,0,10),$J$13:$J$61)*$B$7 | L22: =J22 | M22: =IF(H22=I22,0,INDEX($J$13:$J$61,I22*7+H22+1))
G23: 1x3 | H23: 1 | I23: 3 | J23: =((1-$B$20)*INDEX($H$2:$N$8,H23+1,I23+1)/$P$10)+$B$20/49 | K23: =SUMPRODUCT(INDEX(Pontos!$B$2:$AX$50,0,11),$J$13:$J$61)*$B$7 | L23: =J23 | M23: =IF(H23=I23,0,INDEX($J$13:$J$61,I23*7+H23+1))
G24: 1x4 | H24: 1 | I24: 4 | J24: =((1-$B$20)*INDEX($H$2:$N$8,H24+1,I24+1)/$P$10)+$B$20/49 | K24: =SUMPRODUCT(INDEX(Pontos!$B$2:$AX$50,0,12),$J$13:$J$61)*$B$7 | L24: =J24 | M24: =IF(H24=I24,0,INDEX($J$13:$J$61,I24*7+H24+1))
G25: 1x5 | H25: 1 | I25: 5 | J25: =((1-$B$20)*INDEX($H$2:$N$8,H25+1,I25+1)/$P$10)+$B$20/49 | K25: =SUMPRODUCT(INDEX(Pontos!$B$2:$AX$50,0,13),$J$13:$J$61)*$B$7 | L25: =J25 | M25: =IF(H25=I25,0,INDEX($J$13:$J$61,I25*7+H25+1))
G26: 1x6 | H26: 1 | I26: 6 | J26: =((1-$B$20)*INDEX($H$2:$N$8,H26+1,I26+1)/$P$10)+$B$20/49 | K26: =SUMPRODUCT(INDEX(Pontos!$B$2:$AX$50,0,14),$J$13:$J$61)*$B$7 | L26: =J26 | M26: =IF(H26=I26,0,INDEX($J$13:$J$61,I26*7+H26+1))
G27: 2x0 | H27: 2 | I27: 0 | J27: =((1-$B$20)*INDEX($H$2:$N$8,H27+1,I27+1)/$P$10)+$B$20/49 | K27: =SUMPRODUCT(INDEX(Pontos!$B$2:$AX$50,0,15),$J$13:$J$61)*$B$7 | L27: =J27 | M27: =IF(H27=I27,0,INDEX($J$13:$J$61,I27*7+H27+1))
G28: 2x1 | H28: 2 | I28: 1 | J28: =((1-$B$20)*INDEX($H$2:$N$8,H28+1,I28+1)/$P$10)+$B$20/49 | K28: =SUMPRODUCT(INDEX(Pontos!$B$2:$AX$50,0,16),$J$13:$J$61)*$B$7 | L28: =J28 | M28: =IF(H28=I28,0,INDEX($J$13:$J$61,I28*7+H28+1))
G29: 2x2 | H29: 2 | I29: 2 | J29: =((1-$B$20)*INDEX($H$2:$N$8,H29+1,I29+1)/$P$10)+$B$20/49 | K29: =SUMPRODUCT(INDEX(Pontos!$B$2:$AX$50,0,17),$J$13:$J$61)*$B$7 | L29: =J29 | M29: =IF(H29=I29,0,INDEX($J$13:$J$61,I29*7+H29+1))
G30: 2x3 | H30: 2 | I30: 3 | J30: =((1-$B$20)*INDEX($H$2:$N$8,H30+1,I30+1)/$P$10)+$B$20/49 | K30: =SUMPRODUCT(INDEX(Pontos!$B$2:$AX$50,0,18),$J$13:$J$61)*$B$7 | L30: =J30 | M30: =IF(H30=I30,0,INDEX($J$13:$J$61,I30*7+H30+1))
G31: 2x4 | H31: 2 | I31: 4 | J31: =((1-$B$20)*INDEX($H$2:$N$8,H31+1,I31+1)/$P$10)+$B$20/49 | K31: =SUMPRODUCT(INDEX(Pontos!$B$2:$AX$50,0,19),$J$13:$J$61)*$B$7 | L31: =J31 | M31: =IF(H31=I31,0,INDEX($J$13:$J$61,I31*7+H31+1))
G32: 2x5 | H32: 2 | I32: 5 | J32: =((1-$B$20)*INDEX($H$2:$N$8,H32+1,I32+1)/$P$10)+$B$20/49 | K32: =SUMPRODUCT(INDEX(Pontos!$B$2:$AX$50,0,20),$J$13:$J$61)*$B$7 | L32: =J32 | M32: =IF(H32=I32,0,INDEX($J$13:$J$61,I32*7+H32+1))
G33: 2x6 | H33: 2 | I33: 6 | J33: =((1-$B$20)*INDEX($H$2:$N$8,H33+1,I33+1)/$P$10)+$B$20/49 | K33: =SUMPRODUCT(INDEX(Pontos!$B$2:$AX$50,0,21),$J$13:$J$61)*$B$7 | L33: =J33 | M33: =IF(H33=I33,0,INDEX($J$13:$J$61,I33*7+H33+1))
G34: 3x0 | H34: 3 | I34: 0 | J34: =((1-$B$20)*INDEX($H$2:$N$8,H34+1,I34+1)/$P$10)+$B$20/49 | K34: =SUMPRODUCT(INDEX(Pontos!$B$2:$AX$50,0,22),$J$13:$J$61)*$B$7 | L34: =J34 | M34: =IF(H34=I34,0,INDEX($J$13:$J$61,I34*7+H34+1))
G35: 3x1 | H35: 3 | I35: 1 | J35: =((1-$B$20)*INDEX($H$2:$N$8,H35+1,I35+1)/$P$10)+$B$20/49 | K35: =SUMPRODUCT(INDEX(Pontos!$B$2:$AX$50,0,23),$J$13:$J$61)*$B$7 | L35: =J35 | M35: =IF(H35=I35,0,INDEX($J$13:$J$61,I35*7+H35+1))
G36: 3x2 | H36: 3 | I36: 2 | J36: =((1-$B$20)*INDEX($H$2:$N$8,H36+1,I36+1)/$P$10)+$B$20/49 | K36: =SUMPRODUCT(INDEX(Pontos!$B$2:$AX$50,0,24),$J$13:$J$61)*$B$7 | L36: =J36 | M36: =IF(H36=I36,0,INDEX($J$13:$J$61,I36*7+H36+1))
G37: 3x3 | H37: 3 | I37: 3 | J37: =((1-$B$20)*INDEX($H$2:$N$8,H37+1,I37+1)/$P$10)+$B$20/49 | K37: =SUMPRODUCT(INDEX(Pontos!$B$2:$AX$50,0,25),$J$13:$J$61)*$B$7 | L37: =J37 | M37: =IF(H37=I37,0,INDEX($J$13:$J$61,I37*7+H37+1))
G38: 3x4 | H38: 3 | I38: 4 | J38: =((1-$B$20)*INDEX($H$2:$N$8,H38+1,I38+1)/$P$10)+$B$20/49 | K38: =SUMPRODUCT(INDEX(Pontos!$B$2:$AX$50,0,26),$J$13:$J$61)*$B$7 | L38: =J38 | M38: =IF(H38=I38,0,INDEX($J$13:$J$61,I38*7+H38+1))
G39: 3x5 | H39: 3 | I39: 5 | J39: =((1-$B$20)*INDEX($H$2:$N$8,H39+1,I39+1)/$P$10)+$B$20/49 | K39: =SUMPRODUCT(INDEX(Pontos!$B$2:$AX$50,0,27),$J$13:$J$61)*$B$7 | L39: =J39 | M39: =IF(H39=I39,0,INDEX($J$13:$J$61,I39*7+H39+1))
G40: 3x6 | H40: 3 | I40: 6 | J40: =((1-$B$20)*INDEX($H$2:$N$8,H40+1,I40+1)/$P$10)+$B$20/49 | K40: =SUMPRODUCT(INDEX(Pontos!$B$2:$AX$50,0,28),$J$13:$J$61)*$B$7 | L40: =J40 | M40: =IF(H40=I40,0,INDEX($J$13:$J$61,I40*7+H40+1))
...

Sheet Validação
A1: Caso | B1: palpite | C1: resultado | D1: esperado | E1: matriz Pontos | F1: dif
A2: oficial: completo | B2: 2x0 | C2: 2x0 | D2: 10 | E2: =INDEX(Pontos!$B$2:$AX$50,15,15) | F2: =E2-D2
A3: oficial: completo 0x0 | B3: 0x0 | C3: 0x0 | D3: 10 | E3: =INDEX(Pontos!$B$2:$AX$50,1,1) | F3: =E3-D3
A4: oficial: intermediário (gols do visitante batem) | B4: 3x0 | C4: 2x0 | D4: 6 | E4: =INDEX(Pontos!$B$2:$AX$50,15,22) | F4: =E4-D4
A5: oficial: intermediário (saldo bate) | B5: 4x1 | C5: 3x0 | D5: 6 | E5: =INDEX(Pontos!$B$2:$AX$50,22,30) | F5: =E5-D5
A6: oficial: básico (só vencedor) | B6: 2x1 | C6: 4x0 | D6: 5 | E6: =INDEX(Pontos!$B$2:$AX$50,29,16) | F6: =E6-D6
A7: oficial: ARMADILHA — empate vs empate dá 5, NÃO 6 | B7: 2x2 | C7: 1x1 | D7: 5 | E7: =INDEX(Pontos!$B$2:$AX$50,9,17) | F7: =E7-D7
A8: oficial: invertido | B8: 2x0 | C8: 0x2 | D8: -2 | E8: =INDEX(Pontos!$B$2:$AX$50,3,15) | F8: =E8-D8
A9: oficial: nenhum | B9: 3x0 | C9: 1x2 | D9: 0 | E9: =INDEX(Pontos!$B$2:$AX$50,10,22) | F9: =E9-D9
A10: oficial: ARMADILHA — gols da casa batem mas é 0 | B10: 1x0 | C10: 1x1 | D10: 0 | E10: =INDEX(Pontos!$B$2:$AX$50,9,8) | F10: =E10-D10
A11: empate exato | B11: 1x1 | C11: 1x1 | D11: 10 | E11: =INDEX(Pontos!$B$2:$AX$50,9,9) | F11: =E11-D11
A12: empate vs outro empate | B12: 1x1 | C12: 2x2 | D12: 5 | E12: =INDEX(Pontos!$B$2:$AX$50,17,9) | F12: =E12-D12
A13: 0x0 vs 1x1 | B13: 0x0 | C13: 1x1 | D13: 5 | E13: =INDEX(Pontos!$B$2:$AX$50,9,1) | F13: =E13-D13
A14: invertido não óbvio | B14: 2x1 | C14: 1x2 | D14: -2 | E14: =INDEX(Pontos!$B$2:$AX$50,10,16) | F14: =E14-D14
A15: invertido mínimo | B15: 1x0 | C15: 0x1 | D15: -2 | E15: =INDEX(Pontos!$B$2:$AX$50,2,8) | F15: =E15-D15
A16: invertido visitante | B16: 0x3 | C16: 3x0 | D16: -2 | E16: =INDEX(Pontos!$B$2:$AX$50,22,4) | F16: =E16-D16
A17: intermediário: gols da casa batem | B17: 2x1 | C17: 2x0 | D17: 6 | E17: =INDEX(Pontos!$B$2:$AX$50,15,16) | F17: =E17-D17
A18: intermediário: saldo bate | B18: 2x1 | C18: 3x2 | D18: 6 | E18: =INDEX(Pontos!$B$2:$AX$50,24,16) | F18: =E18-D18
A19: básico: nada bate além do vencedor | B19: 3x1 | C19: 1x0 | D19: 5 | E19: =INDEX(Pontos!$B$2:$AX$50,8,23) | F19: =E19-D19
A20: intermediário visitante: saldo -1 bate | B20: 0x1 | C20: 1x2 | D20: 6 | E20: =INDEX(Pontos!$B$2:$AX$50,10,2) | F20: =E20-D20
A21: básico visitante | B21: 0x2 | C21: 1x4 | D21: 5 | E21: =INDEX(Pontos!$B$2:$AX$50,12,3) | F21: =E21-D21
A22: palpite empate, resultado visitante: 0 (não é invertido) | B22: 2x2 | C22: 0x1 | D22: 0 | E22: =INDEX(Pontos!$B$2:$AX$50,2,17) | F22: =E22-D22
A23: completo placar alto | B23: 5x0 | C23: 5x0 | D23: 10 | E23: =INDEX(Pontos!$B$2:$AX$50,36,36) | F23: =E23-D23
A26: SOMA |dif| (tem que ser 0): | F26: =SUMPRODUCT(ABS(F2:F23))

Sheet Política
A1: Conteúdo oficial em bolao/POLITICA.md — congelado 10/06/2026. LIDER=colar no modal | PELOTAO=EV+desempate divergente | CACADOR=variância nos jogos com multiplicador. Exceções de λ: SÓ as 3 da lista fechada, teto ±10%.

Sheet Log
A1: data | B1: jogo | C1: fase | D1: odds (5) | E1: λT | F1: S | G1: λcasa | H1: λfora | I1: flags | J1: exceção? | K1: palpite | L1: EV | M1: margem | N1: modal pelotão | O1: estado | P1: racional | Q1: resultado | R1: pontos
A2: 46184 | B2: DRY-RUN México x ? (odds fictícias) | C2: 1 | D2: 2.05/1.85/1.95/3.40/4.20 | E2: 2.57 | F2: 0.5 | G2: 1.535 | H2: 1.035 | I2: estreia | J2: não | K2: 1x0 | L2: 3.0570822 | M2: 0.0025819103 | N2: - | O2: PELOTAO | P2: DRY-RUN smoke test | Q2: - | R2: -
A3: 46184 | B3: México x África do Sul (ABERTURA, Azteca) | C3: 1 | D3: 2.14/1.71/1.43/4.45/8.25 | E3: 2.453 | F3: 1.227 | G3: 1.84 | H3: 0.613 | I3: estreia | J3: não | K3: 1x0 | L3: 4.3187 | M3: 0.0629 | N3: 2x1/2x0 (ChatGPT 2x0/2x1, Gemini Pro+Flash 2x1) | O3: PELOTAO | P3: FRONTEIRA: divergi do modal {2x1,2x0}; 1x0 = maior P_exato da grade (14.9%), custo 0.06 EV; T-80, mediana 12 casas soft | Q3: 2x0 | R3: 6
A4: 46184 | B4: Coreia do Sul x Rep. Tcheca | C4: 1 | D4: 2.21/1.67/2.61/3.05/3.0 | E4: 2.4 | F4: 0.021 | G4: 1.211 | H4: 1.19 | I4: estreia | J4: não | K4: 1x0 | L4: 2.3248 | M4: 0.0516 | N4: KOR vence (prior: 0% empate no grupo); amostra única 2x1 | O4: PELOTAO | P4: T-60, mediana 10-13 casas; escalações ok (Son falso 9, Schick CF) | Q4: 2x1 | R4: 6
